Workbook

Sheet BASE
A1: Colaborador | B1: Funcao | C1: Tipo Premiacao | D1: Premiacao
A2: Amanda | B2: Atendente | C2: Acumulada | D2: Pacotes
A3: Camila | B3: Coordenadora | C3: Acumulada | D3: Pacotes
A4: Larissa | B4: Passadeira | C4: Acumulada | D4: Produção
A5: Vera | B5: Passadeira | C5: Acumulada | D5: Produção
A6: Simone | B6: Lavadeira | C6: Acumulada
A7: Bianca | B7: Atendente | C7: Loja | D7: Pacotes
A8: Fernanda | B8: Atendente | C8: Loja | D8: Pacotes
A9: Beatriz | B9: Atendente | C9: Loja | D9: Pacotes
A10: Carolina | B10: Atendente | C10: Loja | D10: Pacotes
A11: Priscila | B11: Atendente | C11: Loja | D11: Pacotes
A13: Rafael | B13: Motorista

Sheet META
A3: JANEIRO - METAS
A5: Loja | B5: Meta R$ | C5: Realizado R$ | D5: Atingimento % | E5: Premiação (R$) | F5: Premiação a Receber | H5: Realizado Total das Lojas | I5: Preço Médio | J5: Pagamento Retirada | K5: % PGmto Retidada | L5: Pagamento Antecipado | M5: % Pagamento Antecipado
A6: Matriz | B6: 50000 | C6: 39903 | D6: =C6/B6 -> 0.79806 | E6: 250 | F6: =ROUNDDOWN(E6*D6,0) -> 199 | H6: =C6 -> 39903 | I6: 23.2 | J6: 29866.85 | K6: 76.13 | L6: 9364.48 | M6: 23.87 | N6: A_P_G_ATUAL_01.pdf
A7: Filial 1 | B7: 50000 | C7: 39167 | D7: =C7/B7 -> 0.78334 | E7: 150 | F7: =ROUNDDOWN(E7*D7,0) -> 117 | H7: =C7 -> 39167 | I7: 21.38 | J7: 21279.29 | K7: 53.62 | L7: 18404.98 | M7: 46.38
A8: Filial 2 | B8: 12000 | C8: 9461 | D8: =C8/B8 -> 0.78841667 | E8: 100 | F8: =ROUNDDOWN(E8*D8,0) -> 78 | H8: =C8 -> 9461 | I8: 25.59 | J8: 7237 | K8: 73.46 | L8: 2614 | M8: 26.54
H9: =SUM(H6:H8) -> 88531 | J9: =SUM(J6:J8) -> 58383.14 | L9: =SUM(L6:L8) -> 30383.46
D10: 👉 TOTAL PRODUÇÃO MATRIZ | E10: PREMIAÇÃO TOTAL ACUMULADA | F10: =SUM(F6:F8) -> 394
A13: FEVEREIRO - METAS
A15: Loja | B15: Meta R$ | C15: Realizado R$ | D15: Atingimento % | E15: Premiação (R$) | F15: Premiação a Receber | H15: Realizado Total das Lojas | I15: Preço Médio | J15: Pagamento Retirada | K15: % PGmto Retidada | L15: Pagamento Antecipado | M15: % Pagamento Antecipado
A16: Matriz | B16: 50000 | C16: 30537 | D16: =C16/B16 -> 0.61074 | E16: 250 | F16: =ROUNDDOWN(E16*D16,0) -> 152 | I16: 20.84 | J16: 21185.98 | K16: 66.07 | L16: 10881 | M16: 33.93 | N16: A_P_G_ATUAL_02.pdf
A17: Filial 1 | B17: 50000 | C17: 32289 | D17: =C17/B17 -> 0.64578 | E17: 150 | F17: =ROUNDDOWN(E17*D17,0) -> 96 | I17: 21.85 | J17: 19833.95 | K17: 58.76 | L17: 13918.5 | M17: 41.24
A18: Filial 2 | B18: 12000 | C18: 6592 | D18: =C18/B18 -> 0.54933333 | E18: 100 | F18: =ROUNDDOWN(E18*D18,0) -> 54 | I18: 22.89 | J18: 4833.88 | K18: 67.47 | L18: 2331 | M18: 32.53
H19: =SUM(C16:C18) -> 69418
D20: 👉 TOTAL PRODUÇÃO MATRIZ | E20: PREMIAÇÃO TOTAL ACUMULADA | F20: =SUM(F16:F18) -> 302
A24: MARÇO - METAS
A26: Loja | B26: Meta R$ | C26: Realizado R$ | D26: Atingimento % | E26: Premiação (R$) | F26: Premiação a Receber | H26: Realizado Total das Lojas | I26: Preço Médio | J26: Pgmto Retirada | K26: % Pgmto Retidada | L26: Pgmto Antecipado | M26: % Pgmto Antecipado
A27: Matriz | B27: =B16 -> 50000 | C27: 47897 | D27: =IFERROR(ROUNDDOWN(C27/B27, 2), 0) -> 0.95 | E27: 250 | F27: =ROUNDDOWN(E27*D27,0) -> 237 | I27: 23.69 | J27: 31985.54 | K27: 69.16 | L27: 14264 | M27: 30.84
A28: Filial 1 | B28: =B17 -> 50000 | C28: 41603 | D28: =IFERROR(ROUNDDOWN(C28/B28, 2), 0) -> 0.83 | E28: 150 | F28: =ROUNDDOWN(E28*D28,0) -> 124 | I28: 22.12 | J28: 28110.4 | K28: 61.53 | L28: 17572 | M28: 38.47
A29: Filial 2 | B29: =B18 -> 12000 | C29: 10667 | D29: =IFERROR(ROUNDDOWN(C29/B29, 2), 0) -> 0.88 | E29: 100 | F29: =ROUNDDOWN(E29*D29,0) -> 88 | I29: 24.58 | J29: 6817.5 | K29: 68.49 | L29: 3137 | M29: 31.51
H30: =SUM(C27:C29) -> 100167
D31: 👉 TOTAL PRODUÇÃO MATRIZ | E31: PREMIAÇÃO TOTAL ACUMULADA | F31: =SUM(F27:F29) -> 449
A35: ABRIL - METAS
A37: Loja | B37: Meta R$ | C37: Realizado R$ | D37: Atingimento % | E37: Premiação (R$) | F37: Premiação a Receber | H37: Realizado Total das Lojas | I37: Preço Médio | J37: Pagamento Retirada | K37: % PGmto Retidada | L37: Pagamento Antecipado | M37: % Pagamento Antecipado | N37: venda pacotes camisas | O37: Clientes Novos | P37: Total tickets Validos | Q37: Media Faturamento dia/Trabalaho
A38: Matriz | B38: 55000 | C38: 35000 | D38: =FLOOR(C38/B38,0.01) -> 0.63 | E38: 250 | F38: =E38*D38 -> 157.5 | I38: 21.66 | J38: 28067.3 | K38: 69.48 | L38: 12326.5 | M38: 30.52 | N38: 10 | O38: 39 | P38: 356 | Q38: 1615.07
A39: Filial 1 | B39: 52000 | C39: 43569 | D39: =FLOOR(C39/B39,0.01) -> 0.83 | E39: 150 | F39: =E39*D39 -> 124.5 | I39: 21.66 | J39: 21867.93 | K39: 56.52 | L39: 16824.87 | M39: 43.48 | N39: 2 | O39: 32 | P39: 462 | Q39: 1547.71
A40: Filial 2 | B40: 15000 | C40: 8526 | D40: =FLOOR(C40/B40,0.01) -> 0.56 | E40: 100 | F40: =E40*D40 -> 56 | I40: 21.94 | J40: 6281.5 | K40: 66.89 | L40: 3109.5 | M40: 33.11 | N40: 2 | O40: 25 | P40: 120 | Q40: 375.64
H41: =SUM(C38:C40) -> 87095
D42: 👉 TOTAL PRODUÇÃO MATRIZ | E42: PREMIAÇÃO TOTAL ACUMULADA | F42: =SUM(F38:F40) -> 338
A45: MAIO - METAS
A47: Loja | B47: Meta R$ | C47: Realizado R$ | D47: Atingimento % | E47: Premiação (R$) | F47: Premiação a Receber | H47: Realizado Total das Lojas | I47: Preço Médio | J47: Pagamento Retirada | K47: % PGmto Retidada | L47: Pagamento Antecipado | M47: % Pagamento Antecipado
A48: Matriz | B48: 55000 | C48: 47046 | D48: =IFERROR(ROUNDDOWN(C48/B48, 2), 0) -> 0.85 | E48: 250 | F48: =ROUNDDOWN(E48*D48,0) -> 212 | I48: ='REFERENCIA PML'!C7 -> 26.95 | J48: 29434.91 | K48: 66.15 | L48: 15061.9 | M48: 33.85
A49: Filial 1 | B49: 52000 | C49: 47730 | D49: =IFERROR(ROUNDDOWN(C49/B49, 2), 0) -> 0.91 | E49: 150 | F49: =ROUNDDOWN(E49*D49,0) -> 136 | I49: ='REFERENCIA PML'!C14 -> 25.84 | J49: 31537.95 | K49: 61.11 | L49: 20073.1 | M49: 38.89
A50: Filial 2 | B50: 15000 | C50: 10988 | D50: =IFERROR(ROUNDDOWN(C50/B50, 2), 0) -> 0.73 | E50: 100 | F50: =ROUNDDOWN(E50*D50,0) -> 73 | I50: ='REFERENCIA PML'!C21 -> 25.34 | J50: 5966.5 | K50: 54.51 | L50: 4978.5 | M50: 45.49
H51: =SUM(C48:C50) -> 105764
D52: 👉 TOTAL PRODUÇÃO MATRIZ | E52: PREMIAÇÃO TOTAL ACUMULADA | F52: =SUM(F48:F50) -> 421
A55: JUNHO - METAS
A57: Loja | B57: Meta R$ | C57: Faturamento R$ | D57: Atingimento % | E57: Premiação (R$) | F57: Premiação a Receber | H57: Realizado Total das Lojas | I57: Preço Médio | J57: Pagamento Retirada | K57: % PGmto Retidada | L57: Pagamento Antecipado | M57: % Pagamento Antecipado
A58: Matriz | B58: 59000 | C58: 39322 | D58: =FLOOR(C58/B58,0.01) -> 0.66 | E58: 250 | F58: =TRUNC(E58*D58, 0) -> 165 | I58: 25.71 | J58: 27033.86 | K58: 66.43 | L58: 13662.94 | M58: 33.57
A59: Filial 1 | B59: 54000 | C59: 47685 | D59: =FLOOR(C59/B59,0.01) -> 0.88 | E59: 150 | F59: =TRUNC(E59*D59, 0) -> 132 | I59: 24.18 | J59: 25502.94 | K59: 57.52 | L59: 18837.87 | M59: 42.48
A60: Filial 2 | B60: 16000 | C60: 10917 | D60: =FLOOR(C60/B60,0.01) -> 0.68 | E60: 100 | F60: =TRUNC(E60*D60, 0) -> 68 | I60: 26.36 | J60: 5665 | K60: 52.76 | L60: 5072.5 | M60: 47.24
...

Sheet REFERENCIA PML
A1: REFERÊNCIA — PML E PAGAMENTO ANTECIPADO POR LOJA E MÊS
A2: Loja | B2: Mês | C2: PML (R$) | D2: Pg Antecip. Loja (R$) | E2: Pg. Anpecip. % | F2: Base de Cálculo
A3: Matriz | B3: Jan | C3: 25.57 | D3: R$ 9.364,48 | E3: 23.87 | F3: Panorama Geral / Estatística Tipo Pagamento
A4: Matriz | B4: Fev | C4: 22.88 | D4: R$ 10.881,00 | E4: 33.93
A5: Matriz | B5: Mar | C5: 26.06 | D5: R$ 14.264,00 | E5: 30.84
A6: Matriz | B6: Abril | C6: 23.91 | D6: 12326.5 | E6: 30.52
A7: Matriz | B7: Maio | C7: 26.95 | D7: 15061.9 | E7: 33.85
A8: Matriz | B8: Junho | C8: =META!I58 -> 25.71 | D8: =META!L58 -> 13662.94 | E8: =META!M58 -> 33.57
A9: Matriz | B9: Julho | C9: =META!I68 -> 23.15 | D9: =META!L68 -> 12238.6 | E9: =META!M68 -> 28.53
A10: Filial 1 | B10: Jan | C10: R$ 21,38 | D10: R$ 18.404,98 | E10: 21.83
A11: Filial 1 | B11: Fev | C11: 22.14 | D11: R$ 13.918,50 | E11: 41.82
A12: Filial 1 | B12: Mar | C12: 22.52 | D12: R$ 17.572,00 | E12: 38.47
A13: Filial 1 | B13: Abril | C13: 21.66 | D13: 16824.87 | E13: 43.48
A14: Filial 1 | B14: Maio | C14: 25.84 | D14: 20073.1 | E14: 38.89
A15: Filial 1 | B15: Junho | C15: =META!I59 -> 24.18 | D15: =META!L59 -> 18837.87 | E15: =META!M59 -> 42.48
A16: Filial 1 | B16: Julho | C16: =META!I69 -> 24.42 | D16: =META!L69 -> 18520.07 | E16: =META!M69 -> 39.99
A17: Filial 2 | B17: Jan | C17: R$ 25,59 | D17: R$ 2.614,00 | E17: 26.54
A18: Filial 2 | B18: Fev | C18: R$ 22,89 | D18: R$ 2.331,00 | E18: 32.53
A19: Filial 2 | B19: Mar | C19: R$ 24,58 | D19: R$ 3.137,00 | E19: 31.51
A20: Filial 2 | B20: Abril | C20: 22.47 | D20: 3109.5 | E20: 33.11
A21: Filial 2 | B21: Maio | C21: 25.34 | D21: 4978.5 | E21: 45.49
A22: Filial 2 | B22: Junho | C22: =META!I60 -> 26.36 | D22: =META!L60 -> 5072.5 | E22: =META!M60 -> 47.24
A23: Filial 2 | B23: Julho | C23: =META!I70 -> 21.59 | D23: =META!L70 -> 3070.72 | E23: =META!M70 -> 28.28

Sheet CONTROLE
A1: JANEIRO
A3: Nome | B3: Loja | C3: tipo | D3: Premiação Loja | E3: Comissão Pacote | F3: Comissão Produção | G3: Assiduidade | H3: Total pago | I3: Quant. pacotes vendidos | J3: Valor pg pacote vendido | K3: Premiação p/ pç extra R$ | L3: Peça Passadas | M3: Extra
A4: =BASE!A13 -> Rafael | B4: =VLOOKUP(TRIM(A4), BASE!A:B, 3, 0) -> #REF! | C4: =#REF! -> #REF! | D4: =META!F10 -> 394 | E4: 0
A5: =BASE!A3 -> Camila | B5: =VLOOKUP(TRIM(A5), BASE!A:B, 3, 0) -> #REF! | C5: =BASE!C3 -> Acumulada | D5: =META!F10 -> 394 | E5: =I5*J4 -> 0 | F5: 0 | G5: 0 | H5: =D5+E5+F5+G5 -> 394 | I5: 7 | J5: 10
A6: =BASE!A4 -> Larissa | B6: =VLOOKUP(TRIM(A6), BASE!A:B, 3, 0) -> #REF! | C6: =BASE!C4 -> Acumulada | D6: =META!F10 -> 394 | E6: =I6*J5 -> 0 | F6: =M6*K6 -> 12 | G6: 0 | H6: =D6+E6+F6+G6 -> 406 | K6: 0.5 | L6: 129 | M6: 24
A7: =BASE!A5 -> Vera | B7: =VLOOKUP(TRIM(A7), BASE!A:B, 3, 0) -> #REF! | C7: =BASE!C5 -> Acumulada | D7: =META!F10 -> 394 | E7: =I7*J6 -> 0 | F7: =M7*K7 -> 383.4 | G7: 0 | H7: =D7+E7+F7+G7 -> 777.4 | K7: 0.3 | L7: 2824 | M7: 1278
A8: =BASE!A6 -> Simone | B8: =VLOOKUP(TRIM(A8), BASE!A:B, 3, 0) -> #REF! | C8: =BASE!C6 -> Acumulada | D8: =META!F10 -> 394 | E8: =I8*J7 -> 0 | H8: =D8+E8+F8+G8 -> 394
A9: =BASE!A7 -> Bianca | B9: =VLOOKUP(TRIM(A9), BASE!A:B, 3, 0) -> #REF! | C9: =BASE!C7 -> Loja | D9: =META!F7 -> 117 | E9: =I9*J9 -> 10 | G9: 0 | H9: =D9+E9+F9+G9 -> 127 | I9: 1 | J9: 10
A10: =BASE!A8 -> Fernanda | B10: =VLOOKUP(TRIM(A10), BASE!A:B, 3, 0) -> #REF! | C10: =BASE!C8 -> Loja | D10: =META!F7 -> 117 | E10: =I10*J10 -> 30 | H10: =D10+E10+F10+G10 -> 147 | I10: 3 | J10: 10
A11: =BASE!A9 -> Beatriz | B11: =VLOOKUP(TRIM(A11), BASE!A:B, 3, 0) -> #REF! | C11: =BASE!C9 -> Loja | D11: =META!F8 -> 78 | E11: =I11*J11 -> 20 | G11: 0 | H11: =D11+E11+F11+G11 -> 98 | I11: 2 | J11: 10
A12: =BASE!A10 -> Carolina | B12: =VLOOKUP(TRIM(A12), BASE!A:B, 3, 0) -> #REF! | C12: =BASE!C10 -> Loja | D12: =META!F8 -> 78 | E12: =I12*J12 -> 0 | G12: 0 | H12: =D12+E12+F12+G12 -> 78 | I12: 0 | J12: 10
A14: FEVEREIRO
A16: Nome | B16: Loja | C16: tipo | D16: Premiação Loja | E16: Comissão Pacote | F16: Comissão Produção | G16: Assiduidade | H16: Total pago | I16: Quant. pacotes vendidos | J16: Valor pg pacote vendido | K16: Premiação p/ pç extra R$ | L16: Peça Passadas | M16: Extra
A17: =BASE!A13 -> Rafael | B17: =VLOOKUP(TRIM(A4), BASE!A:B, 3, 0) -> #REF! | C17: =BASE!C3 -> Acumulada | E17: 0 | J17: 10
A18: =BASE!A3 -> Camila | B18: =VLOOKUP(TRIM(A5), BASE!A:B, 3, 0) -> #REF! | C18: =BASE!C4 -> Acumulada | D18: =META!F20 -> 302 | E18: =I18*J17 -> 10 | F18: 0 | G18: 300 | H18: =D18+E18+F18+G18 -> 612 | I18: 1 | J18: 10
A19: =BASE!A4 -> Larissa | B19: =VLOOKUP(TRIM(A6), BASE!A:B, 3, 0) -> #REF! | C19: =BASE!C5 -> Acumulada | D19: =META!F20 -> 302 | E19: =I19*J18 -> 0 | F19: =M19*K19 -> 95.5 | G19: 300 | H19: =D19+E19+F19+G19 -> 697.5 | K19: 0.5 | L19: 1245 | M19: 191
A20: =BASE!A5 -> Vera | B20: =VLOOKUP(TRIM(A7), BASE!A:B, 3, 0) -> #REF! | C20: =BASE!C6 -> Acumulada | D20: =META!F20 -> 302 | E20: =I20*J19 -> 0 | F20: =M20*K20 -> 103.5 | G20: 300 | H20: =D20+E20+F20+G20 -> 705.5 | K20: 0.3 | L20: 1590 | M20: 345
A21: =BASE!A6 -> Simone | B21: =VLOOKUP(TRIM(A8), BASE!A:B, 3, 0) -> #REF! | C21: =BASE!C6 -> Acumulada | D21: 0 | E21: =I21*J20 -> 0 | H21: =D21+E21+F21+G21 -> 0
A22: =BASE!A7 -> Bianca | B22: =VLOOKUP(TRIM(A9), BASE!A:B, 3, 0) -> #REF! | C22: =BASE!C8 -> Loja | D22: =META!F17 -> 96 | E22: =I22*J22 -> 30 | G22: 300 | H22: =D22+E22+F22+G22 -> 426 | I22: 3 | J22: 10
A23: =BASE!A8 -> Fernanda | B23: =VLOOKUP(TRIM(A10), BASE!A:B, 3, 0) -> #REF! | C23: =BASE!C9 -> Loja | D23: =META!F17 -> 96 | E23: =I23*J23 -> 20 | H23: =D23+E23+F23+G23 -> 116 | I23: 2 | J23: 10
A24: =BASE!A9 -> Beatriz | B24: =VLOOKUP(TRIM(A11), BASE!A:B, 3, 0) -> #REF! | C24: =BASE!C10 -> Loja | D24: =META!F18 -> 54 | E24: =I24*J24 -> 20 | G24: 300 | H24: =D24+E24+F24+G24 -> 374 | I24: 2 | J24: 10
A25: =BASE!A10 -> Carolina | B25: =VLOOKUP(TRIM(A12), BASE!A:B, 3, 0) -> #REF! | C25: =BASE!C10 -> Loja | D25: =META!F18 -> 54 | E25: =I25*J25 -> 0 | G25: 300 | H25: =D25+E25+F25+G25 -> 354 | I25: 0 | J25: 10
A27: MARÇO
A29: Nome | B29: Loja | C29: tipo | D29: Premiação Loja | E29: Comissão Pacote | F29: Comissão Produção | G29: Assiduidade | H29: Total pago | I29: Quant. pacotes vendidos | J29: Valor pg pacote vendido | K29: Premiação p/ pç extra R$ | L29: Peça Passadas | M29: Extra
A30: =BASE!A13 -> Rafael | B30: =VLOOKUP(TRIM(A4), BASE!A:B, 3, 0) -> #REF! | C30: =#REF! -> #REF! | D30: =META!F31 -> 449 | E30: =I30*J30 -> 10 | F30: 0 | G30: 300 | H30: =G30+D30+E30 -> 759 | I30: 1 | J30: 10
A31: =BASE!A3 -> Camila | B31: =VLOOKUP(TRIM(A5), BASE!A:B, 3, 0) -> #REF! | C31: =BASE!C3 -> Acumulada | D31: =META!F31 -> 449 | E31: =I31*J31 -> 80 | F31: 0 | G31: 300 | H31: =D31+E31+F31+G31 -> 829 | I31: 8 | J31: 10
A32: =BASE!A4 -> Larissa | B32: =VLOOKUP(TRIM(A6), BASE!A:B, 3, 0) -> #REF! | C32: =BASE!C4 -> Acumulada | D32: =META!F31 -> 449 | E32: 0 | F32: =M32*K32 -> 147.5 | G32: 300 | H32: =D32+E32+F32+G32 -> 896.5 | I32: 0 | J32: 0 | K32: 0.5 | L32: 1834 | M32: 295
A33: =BASE!A5 -> Vera | B33: =VLOOKUP(TRIM(A7), BASE!A:B, 3, 0) -> #REF! | C33: =BASE!C5 -> Acumulada | D33: =META!F31 -> 449 | E33: 0 | F33: =M33*K33 -> 160.8 | G33: 300 | H33: =D33+E33+F33+G33 -> 909.8 | I33: 0 | J33: 0 | K33: 0.3 | L33: 1859 | M33: 536
A34: =BASE!A6 -> Simone | B34: =VLOOKUP(TRIM(A8), BASE!A:B, 3, 0) -> #REF! | C34: =BASE!C6 -> Acumulada | D34: =META!F31 -> 449 | E34: 0 | F34: 0 | G34: 300 | H34: =D34+E34+F34+G34 -> 749 | I34: 0 | J34: 0
A35: =BASE!A7 -> Bianca | B35: =VLOOKUP(TRIM(A9), BASE!A:B, 3, 0) -> #REF! | C35: =BASE!C7 -> Loja | D35: =META!F28 -> 124 | E35: =I35*J35 -> 10 | F35: 0 | G35: 0 | H35: =D35+E35+F35+G35 -> 134 | I35: 1 | J35: 10
A36: =BASE!A8 -> Fernanda | B36: =VLOOKUP(TRIM(A10), BASE!A:B, 3, 0) -> #REF! | C36: =BASE!C8 -> Loja | D36: =META!F28 -> 124 | E36: =I36*J36 -> 20 | F36: 0 | G36: 300 | H36: =D36+E36+F36+G36 -> 444 | I36: 2 | J36: 10
A37: =BASE!A9 -> Beatriz | B37: =VLOOKUP(TRIM(A11), BASE!A:B, 3, 0) -> #REF! | C37: =BASE!C9 -> Loja | D37: =META!F29 -> 88 | E37: =I37*J37 -> 40 | F37: 0 | G37: 300 | H37: =D37+E37+F37+G37 -> 428 | I37: 4 | J37: 10
A38: =BASE!A10 -> Carolina | B38: =VLOOKUP(TRIM(A12), BASE!A:B, 3, 0) -> #REF! | C38: =BASE!C10 -> Loja | D38: =META!F27 -> 237 | E38: =I38*J38 -> 10 | F38: 0 | G38: 300 | H38: =D38+E38+F38+G38 -> 547 | I38: 1 | J38: 10
A39: TOTAL | D39: =SUM(D30:D38) -> 2818 | E39: =SUM(E30:E38) -> 170 | F39: =SUM(F30:F38) -> 308.3 | G39: =SUM(G30:G38) -> 2400 | H39: =SUM(H30:H38) -> 5696.3 | I39: =SUM(I30:I38) -> 17 | L39: =SUM(L32:L33) -> 3693 | M39: =SUM(M30:M38) -> 831 | N39: =SUM(L39:M39) -> 4524
A42: ABRIL
A44: Nome | B44: Loja | C44: tipo | D44: Premiação Loja | E44: Comissão Pacote | F44: Comissão Produção | G44: Assiduidade | H44: Total pago | I44: Quant. pacotes vendidos | J44: Valor pg pacote vendido | K44: Premiação p/ pç extra R$ | L44: Peça Passadas | M44: Extra
A45: =BASE!A13 -> Rafael | B45: MATRIZ | C45: Acumulada | D45: =META!F42 -> 338 | E45: =I45*J45 -> 0 | F45: 0 | G45: 300 | H45: =G45+D45+E45 -> 638 | I45: 0 | J45: 10
A46: =BASE!A3 -> Camila | B46: MATRIZ | C46: Acumulada | D46: =META!F42 -> 338 | E46: =I46*J46 -> 80 | F46: 0 | G46: 300 | H46: =D46+E46+F46+G46 -> 718 | I46: 8 | J46: 10
A47: =BASE!A4 -> Larissa | B47: MATRIZ | C47: Acumulada | D47: =META!F42 -> 338 | E47: 0 | F47: =M47*K47 -> 310.5 | G47: 300 | H47: =D47+E47+F47+G47 -> 948.5 | I47: 0 | J47: 0 | K47: 0.5 | L47: 2063 | M47: 621
A48: =BASE!A5 -> Vera | B48: MATRIZ | C48: Acumulada | D48: =META!F42 -> 338 | E48: 0 | F48: =M48*K48 -> 103.5 | G48: 0 | H48: =D48+E48+F48+G48 -> 441.5 | I48: 0 | J48: 0 | K48: 0.3 | L48: 1404 | M48: 345
...

Sheet RAFAEL
B2: Rafael | I2: MATRIZ | M2: FILIAL 1 | Q2: FILIAL 2
A3: MÊS | B3: Total Pacotes Vendidos | C3: COMISSÃO | D3: Premiação | Pacotes | | E3: Premiação | Meta | loja | F3: Total | G3: Assiduidade R$ | H3: Total Recebido R$ | I3: PMO R$ | J3: PML | K3: Pg Antecipado Operador % | L3: Pg Antecipado Lj % | M3: PMO R$ | N3: PML | O3: Pg Antecipado Operador % | P3: Pg Antecipado Lj % | Q3: PMO R$ | R3: PML | S3: % Pg Antecipado
A4: JANEIRO | C4: 0 | E4: =CONTROLE!D4 -> 394 | F4: =D4+E4 -> 394 | H4: =SUM(F4:G4) -> 394 | I4: =802/35 -> 22.914286 | J4: ='REFERENCIA PML'!C3 -> 25.57 | K4: =430/802 -> 0.5361596 | L4: ='REFERENCIA PML'!E3 -> 23.87 | M4: R$ 29,50 | O4: 0.0032 | Q4: - | S4: -
A5: FEVEREIRO | D5: =CONTROLE!J17 -> 10 | F5: =D5+E5 -> 10 | H5: =SUM(F5:G5) -> 10 | I5: =82/ 2 -> 41 | J5: ='REFERENCIA PML'!C4 -> 22.88 | K5: =82/82 -> 1 | L5: ='REFERENCIA PML'!E4 -> 33.93 | M5: R$ 21,40 | O5: 0 | Q5: — | S5: —
A6: MARÇO | B6: =CONTROLE!I30 -> 1 | D6: =CONTROLE!E30 -> 10 | E6: =CONTROLE!D30 -> 449 | F6: =D6+E6 -> 459 | G6: 300 | H6: =SUM(F6:G6) -> 759 | I6: R$ 13,28 | J6: ='REFERENCIA PML'!C5 -> 26.06 | K6: 0.035 | L6: ='REFERENCIA PML'!E5 -> 30.84 | M6: R$ 32,67 | O6: 0 | Q6: R$ 17,00 | S6: 0
A7: ABRIL | B7: =CONTROLE!I45 -> 0 | D7: =CONTROLE!E45 -> 0 | E7: =CONTROLE!D45 -> 338 | F7: =D7+E7 -> 338 | G7: 300 | H7: =SUM(F7:G7) -> 638 | I7: 36 | J7: ='REFERENCIA PML'!C6 -> 23.91 | K7: 0 | L7: ='REFERENCIA PML'!E6 -> 30.52 | M7: 21
A8: MAIO | B8: 0 | D8: 0 | E8: =CONTROLE!D61 -> 421 | F8: =D8+E8 -> 421 | G8: =CONTROLE!G61 -> 300 | H8: =SUM(F8:G8) -> 721 | I8: =37/2 -> 18.5 | J8: ='REFERENCIA PML'!C7 -> 26.95 | K8: 0 | L8: ='REFERENCIA PML'!E7 -> 33.85
A9: JUNHO | B9: 0 | D9: 0 | E9: =0 -> 0 | F9: =D9+E9 -> 0 | G9: 80 | H9: =SUM(F9:G9) -> 80
A10: JULHO | B10: =CONTROLE!I93 -> 0 | D10: =CONTROLE!E93 -> 0 | E10: =CONTROLE!D93 -> 0 | F10: =D10+E10 -> 0 | G10: 0 | H10: =SUM(F10:G10) -> 0 | I10: — | J10: — | K10: — | L10: — | M10: — | N10: — | O10: — | P10: — | Q10: — | R10: — | S10: — | T10: Verificar Helena
A11: AGOSTO
A12: SETEMBRO
A13: OUTUBRO
A14: NOVEMBRO
A15: DEZEMBRO

Sheet CAMILA
A2: Camila | I2: MATRIZ | N2: FILIAL 1 | Q2: FILIAL 2
A3: MÊS | B3: Total Pacotes Vendidos | C3: COMISSÃO | D3: Premiação | Pacotes | | E3: Premiação | Meta | R$ | F3: Total | G3: Assiduidade R$ | H3: Total Recebido R$ | I3: PMO R$ | J3: PMO/PML | K3: PML | L3: Pg Antecip. Operador % | M3: Pg Antecip. Lj % | N3: PMO R$ | O3: PML | P3: % Pg Antecipado | Q3: PMO R$ | R3: PML | S3: % Pg Antecipado
A4: JANEIRO | B4: =CONTROLE!I5 -> 7 | C4: 0 | D4: =CONTROLE!E5 -> 0 | E4: =META!F10 -> 394 | F4: =D4+E4 -> 394 | H4: =SUM(F4:G4) -> 394 | I4: =9007.63/323 -> 27.887399 | J4: 0.98 | K4: ='REFERENCIA PML'!C3 -> 25.57 | L4: =3424/ 9007.63 -> 0.38012219 | M4: ='REFERENCIA PML'!E3 -> 23.87 | N4: — | O4: — | P4: — | Q4: — | R4: — | S4: —
A5: FEVEREIRO | B5: =CONTROLE!I18 -> 1 | D5: =CONTROLE!E18 -> 10 | E5: =META!F20 -> 302 | F5: =D5+E5 -> 312 | G5: 300 | H5: =SUM(F5:G5) -> 612 | I5: 22.49 | J5: 0.999 | K5: ='REFERENCIA PML'!C4 -> 22.88 | L5: =3427/5578.5 -> 0.61432285 | M5: ='REFERENCIA PML'!E4 -> 33.93 | N5: — | O5: — | P5: — | Q5: — | R5: — | S5: —
A6: MARÇO | B6: 8 | D6: =CONTROLE!E31 -> 80 | E6: =META!F31 -> 449 | F6: =D6+E6 -> 529 | G6: 300 | H6: =SUM(F6:G6) -> 829 | I6: R$ 24,45 | J6: 1.032 | K6: ='REFERENCIA PML'!C5 -> 26.06 | L6: 0.5761 | M6: ='REFERENCIA PML'!E5 -> 30.84 | N6: — | O6: — | P6: — | Q6: — | R6: — | S6: —
A7: ABRIL | B7: =CONTROLE!I46 -> 8 | D7: =CONTROLE!E46 -> 80 | E7: =CONTROLE!D46 -> 338 | F7: =D7+E7 -> 418 | G7: 300 | H7: =SUM(F7:G7) -> 718 | I7: 22.92 | K7: ='REFERENCIA PML'!C6 -> 23.91 | L7: 0.549 | M7: ='REFERENCIA PML'!E6 -> 30.52
A8: MAIO | B8: 3 | D8: =CONTROLE!E62 -> 70 | E8: =CONTROLE!D62 -> 421 | F8: =D8+E8 -> 491 | G8: =CONTROLE!G62 -> 300 | H8: =SUM(F8:G8) -> 791 | I8: =11230.35/404 -> 27.797896 | K8: ='REFERENCIA PML'!C7 -> 26.95 | L8: 0.4401 | M8: ='REFERENCIA PML'!E7 -> 33.85
A9: JUNHO | B9: =CONTROLE!I78 -> 3 | D9: =CONTROLE!E78 -> 30 | E9: =CONTROLE!D78 -> 365 | F9: =D9+E9 -> 395 | G9: =CONTROLE!G78 -> 300 | H9: =SUM(F9:G9) -> 695 | I9: =10232.44/360 -> 28.423444 | K9: ='REFERENCIA PML'!C8 -> 25.71 | L9: =5124.94/10232.44 -> 0.50085219 | M9: ='REFERENCIA PML'!E8 -> 33.57
A10: JULHO | B10: 0 | D10: 0 | E10: 0 | F10: 0 | G10: 0 | H10: 0 | I10: — | J10: — | K10: — | L10: — | M10: — | N10: — | O10: — | P10: — | Q10: — | R10: — | S10: — | T10: Férias
A11: AGOSTO
A12: SETEMBRO
A13: OUTUBRO
A14: NOVEMBRO
A15: DEZEMBRO | F15: =D15+E15 -> 0

Sheet FERNANDA
A2: Fernanda | I2: MATRIZ | N2: FILIAL 1 | R2: FILIAL 2
A3: MÊS | B3: Total Pacotes Vendidos | C3: COMISSÃO | D3: Premiação | Pacotes | | E3: Premiação | Meta | loja | F3: Total | G3: Assiduidade R$ | H3: Total Recebido R$ | I3: PMO R$ | J3: PMO/PML | K3: PML R$ | L3: Pg Antecipado Operador % | M3: Pg Antecipado Lj % | N3: PMO R$ | O3: PML R$ | P3: % Pg Antecipado | Q3: % Pg Antecipado Lj | R3: PMO R$ | S3: PMO/PML | T3: % Pg Antecipado
A4: JANEIRO | B4: =CONTROLE!I10 -> 3 | C4: 0 | D4: =CONTROLE!E10 -> 30 | E4: =CONTROLE!D10 -> 117 | F4: =D4+E4 -> 147 | H4: =SUM(F4:G4) -> 147 | I4: — | J4: — | L4: — | N4: R$ 20,11 | O4: ='REFERENCIA PML'!C10 -> R$ 21,38 | P4: 0.4751 | Q4: ='REFERENCIA PML'!E10 -> 21.83 | R4: — | S4: — | T4: —
A5: FEVEREIRO | B5: =CONTROLE!I23 -> 2 | D5: =CONTROLE!E23 -> 20 | E5: =META!F18 -> 54 | F5: =D5+E5 -> 74 | G5: 0 | H5: =SUM(F5:G5) -> 74 | I5: =1429/67 -> 21.328358 | J5: 0.914 | K5: ='REFERENCIA PML'!C4 -> 22.88 | L5: =1378/1429 -> 0.96431071 | M5: ='REFERENCIA PML'!E4 -> 33.93 | N5: R$ 19,15 | O5: ='REFERENCIA PML'!C11 -> 22.14 | P5: 0.4678 | Q5: ='REFERENCIA PML'!E11 -> 41.82 | R5: — | S5: 0.728 | T5: —
A6: MARÇO | B6: =CONTROLE!I36 -> 2 | D6: =CONTROLE!E36 -> 20 | E6: =CONTROLE!D36 -> 124 | F6: =D6+E6 -> 144 | G6: 300 | H6: =SUM(F6:G6) -> 444 | I6: — | J6: — | K6: ='REFERENCIA PML'!C5 -> 26.06 | L6: — | M6: ='REFERENCIA PML'!E5 -> 30.84 | N6: R$ 19,52 | O6: ='REFERENCIA PML'!C12 -> 22.52 | P6: 0.5168 | Q6: ='REFERENCIA PML'!E12 -> 38.47 | R6: — | S6: — | T6: —
A7: ABRIL | B7: =CONTROLE!I51 -> 1 | D7: =CONTROLE!E51 -> 10 | E7: =CONTROLE!D51 -> 124.5 | F7: =D7+E7 -> 134.5 | G7: 300 | H7: =SUM(F7:G7) -> 434.5 | I7: — | J7: — | K7: ='REFERENCIA PML'!C6 -> 23.91 | L7: — | M7: ='REFERENCIA PML'!E6 -> 30.52 | N7: 19.71 | O7: ='REFERENCIA PML'!C14 -> 25.84 | P7: 0.47 | Q7: ='REFERENCIA PML'!E13 -> 43.48 | R7: — | S7: — | T7: —
A8: MAIO | B8: =CONTROLE!I67 -> 5 | D8: =CONTROLE!E67 -> 50 | E8: =CONTROLE!D67 -> 136 | F8: =D8+E8 -> 186 | G8: =CONTROLE!G67 -> 300 | H8: =SUM(F8:G8) -> 486 | K8: ='REFERENCIA PML'!C7 -> 26.95 | M8: ='REFERENCIA PML'!E7 -> 33.85 | N8: =23717.17/937 -> 25.311814 | O8: ='REFERENCIA PML'!C14 -> 25.84 | P8: =8645/23717.7 -> 0.36449571 | Q8: ='REFERENCIA PML'!E14 -> 38.89
A9: JUNHO | B9: =CONTROLE!I68 -> 0 | D9: =CONTROLE!E68 -> 0 | E9: =CONTROLE!D83 -> 132 | F9: =D9+E9 -> 132 | G9: =CONTROLE!G83 -> 300 | H9: =SUM(F9:G9) -> 432 | K9: ='REFERENCIA PML'!C9 -> 23.15 | M9: ='REFERENCIA PML'!E9 -> 28.53 | N9: =12152.6/538 -> 22.588476 | O9: ='REFERENCIA PML'!C15 -> 24.18 | P9: =6233/12152.6 -> 0.51289436 | Q9: ='REFERENCIA PML'!E15 -> 42.48
A10: JULHO | B10: =CONTROLE!I99 -> 7 | D10: =CONTROLE!E99 -> 70 | E10: =CONTROLE!D99 -> 129 | F10: =D10+E10 -> 199 | G10: =CONTROLE!G99 -> 300 | H10: =SUM(F10:G10) -> 499 | I10: =4031.0004/284 -> 14.193663 | J10: =I10/K10 -> 0.61311721 | K10: ='REFERENCIA PML'!C9 -> 23.15 | L10: =1664.0004/4031.0004 -> 0.41280085 | M10: ='REFERENCIA PML'!E9 -> 28.53 | N10: =16373.34/741 -> 22.096275 | O10: ='REFERENCIA PML'!C16 -> 24.42 | P10: =7343.34/16373.34 -> 0.44849371 | Q10: ='REFERENCIA PML'!E16 -> 39.99 | R10: — | S10: — | T10: —
A11: AGOSTO
A12: SETEMBRO
A13: OUTUBRO
A14: NOVEMBRO
A15: DEZEMBRO

Sheet BIANCA
B2: BIANCA | H2: MATRIZ | M2: FILIAL 1 | Q2: FILIAL 2 | V2: Alvejamento | W2: Hidratação | X2: kits | Y2: Demais Serviços | Z2: SOFT REVIT. | AA2: SOFT AMIDON.
A3: MÊS | B3: Total Pacotes Vendidos | C3: Premiação | Pacotes | | D3: Premiação | Meta | loja | E3: Total | F3: Assiduidade R$ | G3: Total Recebido R$ | H3: PMO R$ | I3: PMO/PML | J3: PML | K3: Pg Antecip. Operador % | L3: % Pg Antecipado Lj | M3: PMO R$ | N3: PML R$ | O3: Pg Antecip. Operador % | P3: % Pg Antecipado Lj | Q3: PMO R$ | R3: PML R$ | S3: Pg Antecip. Operador % | T3: % Pg Antecipado Lj
A4: JANEIRO | B4: - | D4: - | E4: 0 | G4: =SUM(E4:F4) -> 0 | H4: - | I4: - | K4: - | M4: - | N4: - | O4: - | Q4: - | R4: - | S4: - | T4: -
A5: FEVEREIRO | B5: - | C5: - | D5: - | E5: - | G5: =SUM(E5:F5) -> 0 | H5: - | I5: - | K5: - | M5: - | N5: - | O5: - | Q5: - | R5: - | S5: - | T5: -
A6: MARÇO | B6: - | C6: - | D6: - | E6: - | F6: 0 | G6: =SUM(E6:F6) -> 0 | H6: 0 | I6: 0.614 | K6: 0 | M6: — | N6: — | O6: — | Q6: — | R6: — | S6: — | T6: —
A7: ABRIL | B7: 0 | C7: 0 | D7: 0 | E7: 0 | F7: 0 | G7: =SUM(E7:F7) -> 0 | H7: 0 | J7: 0 | K7: 0
A8: MAIO | B8: 0 | C8: 0 | D8: =CONTROLE!D69 -> 136 | E8: =C8+D8 -> 136 | F8: =CONTROLE!G66 -> 300 | G8: =SUM(E8:F8) -> 436 | H8: 16.94 | J8: ='REFERENCIA PML'!C7 -> 26.95 | K8: 0.1079 | L8: ='REFERENCIA PML'!E7 -> 33.85 | M8: =10004.75/461 -> 21.702278 | N8: ='REFERENCIA PML'!C14 -> 25.84 | O8: =3766.5/10004.75 -> 0.37647118 | P8: ='REFERENCIA PML'!E14 -> 38.89 | S8: ='REFERENCIA PML'!H14 | V8: 1 | Z8: 1
A9: JUNHO | B9: =CONTROLE!I85 -> 1 | C9: =CONTROLE!J85 -> 10 | D9: =CONTROLE!D85 -> 132 | E9: =C9+D9 -> 142 | F9: =CONTROLE!G85 -> 300 | G9: =SUM(E9:F9) -> 442 | H9: =1001/41 -> 24.414634 | J9: ='REFERENCIA PML'!C8 -> 25.71 | K9: =571/1001 -> 0.57042957 | L9: ='REFERENCIA PML'!E8 -> 33.57 | M9: =13231.87/535 -> 24.732467 | N9: ='REFERENCIA PML'!C15 -> 24.18 | O9: =6554.87/13231.87 -> 0.49538501 | P9: ='REFERENCIA PML'!E15 -> 42.48 | Q9: =832.5/39 -> 21.346154 | R9: ='REFERENCIA PML'!C22 -> 26.36 | S9: =483.5/832.5 -> 0.58078078 | T9: ='REFERENCIA PML'!E22 -> 47.24
A10: JULHO | B10: =CONTROLE!I101 -> 3 | C10: =CONTROLE!E101 -> 30 | D10: =CONTROLE!D101 -> 129 | E10: =C10+D10 -> 159 | F10: =CONTROLE!G101 -> 300 | G10: =SUM(E10:F10) -> 459 | H10: =679/61 -> 11.131148 | I10: =H10/J10 -> 0.48082711 | J10: ='REFERENCIA PML'!C9 -> 23.15 | K10: =0/679 -> 0 | L10: ='REFERENCIA PML'!E9 -> 28.53 | M10: =16947.661/739 -> 22.933235 | N10: ='REFERENCIA PML'!C16 -> 24.42 | O10: =7562.7302/16947.661 -> 0.44624035 | P10: ='REFERENCIA PML'!E16 -> 39.99 | Q10: =1156.9998/56 -> 20.660711 | R10: ='REFERENCIA PML'!C23 -> 21.59 | S10: =175/1156.9998 -> 0.15125327 | T10: ='REFERENCIA PML'!E23 -> 28.28
A11: AGOSTO

Sheet BEATRIZ
A2: Beatriz | I2: MATRIZ | L2: FILIAL 1 | O2: FILIAL 2 | S2: Alvejamento | T2: Hidratação | U2: Kit | V2: Demais serviços
A3: MÊS | B3: Total Pacotes Vendidos | C3: COMISSÃO | D3: Premiação | Pacotes | | E3: Premiação | Meta | loja R$ | F3: Total | G3: Assiduidade R$ | H3: Total Recebido R$ | I3: PMO R$ | J3: PML | K3: % Pg Antecipado | L3: PMO R$ | M3: PML | N3: % Pg Antecipado | O3: PMO R$ | P3: PML | Q3: Pg Antecip. Operador % | R3: Pg Antecipado Lj %
A4: JANEIRO | B4: =CONTROLE!I11 -> 2 | C4: 0 | D4: =CONTROLE!E11 -> 20 | E4: =CONTROLE!D11 -> 78 | F4: =D4+E4 -> 98 | H4: =SUM(F4:G4) -> 98 | I4: — | J4: — | K4: — | L4: — | M4: — | N4: — | O4: R$ 23,71 | P4: ='REFERENCIA PML'!C17 -> R$ 25,59 | Q4: 0.3271 | R4: ='REFERENCIA PML'!E17 -> 26.54
A5: FEVEREIRO | B5: =CONTROLE!I24 -> 2 | D5: =CONTROLE!E24 -> 20 | E5: =META!F17 -> 96 | F5: =D5+E5 -> 116 | G5: 300 | H5: =SUM(F5:G5) -> 416 | I5: — | J5: — | K5: — | L5: R$ 13,00 | M5: ='REFERENCIA PML'!C11 -> 22.14 | N5: 0.0009 | O5: R$ 24,09 | P5: ='REFERENCIA PML'!C18 -> R$ 22,89 | Q5: 0.8014 | R5: ='REFERENCIA PML'!E18 -> 32.53
A6: MARÇO | B6: =CONTROLE!I37 -> 4 | D6: =CONTROLE!E37 -> 40 | E6: =CONTROLE!D37 -> 88 | F6: =D6+E6 -> 128 | G6: 300 | H6: =SUM(F6:G6) -> 428 | I6: — | J6: — | K6: — | L6: — | M6: — | N6: — | O6: R$ 24,18 | P6: ='REFERENCIA PML'!C19 -> R$ 24,58 | Q6: 0.6529 | R6: ='REFERENCIA PML'!E19 -> 31.51
A7: ABRIL | B7: =CONTROLE!I52 -> 1 | D7: =CONTROLE!E52 -> 10 | E7: =CONTROLE!D52 -> 56 | F7: =D7+E7 -> 66 | G7: 300 | H7: =SUM(F7:G7) -> 366 | I7: — | O7: 22 | P7: ='REFERENCIA PML'!C20 -> 22.47 | Q7: 0.394 | R7: ='REFERENCIA PML'!E20 -> 33.11
A8: MAIO | B8: =CONTROLE!I70 -> 4 | D8: =CONTROLE!E70 -> 40 | E8: =CONTROLE!D70 -> 73 | F8: =D8+E8 -> 113 | G8: =CONTROLE!G70 -> 300 | H8: =SUM(F8:G8) -> 413 | O8: =6869/267 -> 25.726592 | P8: ='REFERENCIA PML'!C21 -> 25.34 | Q8: =3474/6869 -> 0.50575047 | R8: ='REFERENCIA PML'!E21 -> 45.49 | S8: 4 | T8: 2 | U8: 0 | V8: 1
A9: JUNHO | B9: =CONTROLE!I87 -> 4 | D9: =CONTROLE!E87 -> 40 | E9: =CONTROLE!D87 -> 68 | F9: =D9+E9 -> 108 | G9: =CONTROLE!G87 -> 250 | H9: =SUM(F9:G9) -> 358 | O9: =5539.5/200 -> 27.6975 | P9: ='REFERENCIA PML'!C22 -> 26.36 | Q9: =2740/5539.5 -> 0.49462948 | R9: ='REFERENCIA PML'!E22 -> 47.24
A10: JULHO | B10: =CONTROLE!I102 -> 1 | D10: =CONTROLE!E102 -> 10 | E10: =CONTROLE!D102 -> 0 | F10: =D10+E10 -> 10 | G10: =CONTROLE!G102 -> 0 | H10: =SUM(F10:G10) -> 10 | I10: — | J10: — | K10: — | L10: — | M10: — | N10: — | O10: =4726.8202/234 -> 20.200086 | P10: ='REFERENCIA PML'!C23 -> 21.59 | Q10: =1570.7201/4726.8202 -> 0.33229952 | R10: ='REFERENCIA PML'!E23 -> 28.28
A11: AGOSTO
A12: SETEMBRO
A13: OUTUBRO
A14: NOVEMBRO
A15: DEZEMBRO

Sheet CAROLINA
A2: Carolina | I2: MATRIZ | M2: FILIAL 1 | R2: FILIAL 2 | X2: Alvejamento
A3: MÊS | B3: Total Pacotes Vendidos | C3: COMISSÃO | D3: Premiação | Pacotes | | E3: Premiação | Meta | loja | F3: Total | G3: Assiduidade R$ | H3: Total Recebido R$ | I3: PMO R$ | J3: PML | K3: Pg Antecip. Operador % | L3: Pg Antecipado lj % | M3: PMO R$ | N3: PMO/PML | O3: PML | P3: Pg Antecip. Operador % | Q3: Pg Antecipado lj % | R3: PMO R$ | S3: PMO/PML | T3: PML | U3: Pg Antecip. Operador % | V3: Pg Antecipado lj %
A4: JANEIRO | B4: =CONTROLE!I12 -> 0 | C4: 0 | D4: =CONTROLE!E12 -> 0 | E4: =CONTROLE!D12 -> 78 | F4: =D4+E4 -> 78 | H4: =SUM(F4:G4) -> 78 | I4: =482/22 -> 21.909091 | J4: ='REFERENCIA PML'!C3 -> 25.57 | K4: =0/482 -> 0 | L4: ='REFERENCIA PML'!E3 -> 23.87 | M4: — | N4: — | O4: ='REFERENCIA PML'!C10 -> R$ 21,38 | P4: — | Q4: ='REFERENCIA PML'!E10 -> 21.83 | R4: =5266.12/185 -> 28.465514 | S4: 1.055 | T4: ='REFERENCIA PML'!C17 -> R$ 25,59 | U4: =929.5/5266.12 -> 0.17650566 | V4: ='REFERENCIA PML'!E17 -> 26.54
A5: FEVEREIRO | B5: =CONTROLE!I25 -> 0 | D5: =CONTROLE!E25 -> 0 | E5: =CONTROLE!D25 -> 54 | F5: =D5+E5 -> 54 | G5: =CONTROLE!G25 -> 300 | H5: =SUM(F5:G5) -> 354 | I5: =3308/119 -> 27.798319 | J5: ='REFERENCIA PML'!C4 -> 22.88 | K5: =674/3308 -> 0.20374849 | L5: ='REFERENCIA PML'!E4 -> 33.93 | M5: =2168/109 -> 19.889908 | N5: 0.874 | O5: ='REFERENCIA PML'!C11 -> 22.14 | P5: =1697.5/2168 -> 0.7829797 | Q5: ='REFERENCIA PML'!E11 -> 41.82 | R5: =2252/116 -> 19.413793 | S5: 0.793 | T5: ='REFERENCIA PML'!C18 -> R$ 22,89 | U5: =419/2252 -> 0.18605684 | V5: ='REFERENCIA PML'!E18 -> 32.53
A6: MARÇO | B6: =CONTROLE!I38 -> 1 | D6: =CONTROLE!E38 -> 10 | E6: =CONTROLE!D38 -> 237 | F6: =D6+E6 -> 247 | G6: 300 | H6: =F6+G6 -> 547 | I6: =21725.1/806 -> 26.954218 | J6: ='REFERENCIA PML'!C5 -> 26.06 | K6: =4854.5/21725.1 -> 0.22345122 | L6: ='REFERENCIA PML'!E5 -> 30.84 | M6: =375/20 -> 18.75 | N6: — | O6: ='REFERENCIA PML'!C12 -> 22.52 | P6: =115/375 -> 0.30666667 | Q6: ='REFERENCIA PML'!E12 -> 38.47 | R6: =1919/99 -> 19.383838 | S6: — | T6: ='REFERENCIA PML'!C19 -> R$ 24,58 | U6: =428/1919 -> 0.22303283 | V6: ='REFERENCIA PML'!E19 -> 31.51
A7: ABRIL | B7: - | D7: - | E7: - | F7: - | G7: 0 | H7: - | I7: - | J7: ='REFERENCIA PML'!C6 -> 23.91 | K7: - | L7: ='REFERENCIA PML'!E6 -> 30.52 | M7: =2439/98 -> 24.887755 | O7: ='REFERENCIA PML'!C13 -> 21.66 | P7: =781/2439 -> 0.3202132 | Q7: ='REFERENCIA PML'!E13 -> 43.48 | R7: 53 | T7: ='REFERENCIA PML'!C21 -> 25.34 | U7: =53/53 -> 1 | V7: ='REFERENCIA PML'!E20 -> 33.11 | W7: FÉRIAS
A8: MAIO | B8: =CONTROLE!I68 -> 0 | D8: =CONTROLE!E68 -> 0 | E8: 0 | F8: =SUM(B8:E8) -> 0 | G8: 0 | H8: =SUM(F8:G8) -> 0 | I8: - | J8: ='REFERENCIA PML'!C7 -> 26.95 | K8: - | L8: ='REFERENCIA PML'!E7 -> 33.85 | M8: =16144.1/632 -> 25.544462 | O8: ='REFERENCIA PML'!C14 -> 25.84 | P8: =7489.6/16144.1 -> 0.4639218 | Q8: ='REFERENCIA PML'!E14 -> 38.89 | R8: =166.5/ 15 -> 11.1 | T8: ='REFERENCIA PML'!C21 -> 25.34 | U8: =60/166.5 -> 0.36036036 | V8: ='REFERENCIA PML'!E21 -> 45.49 | X8: 1
A9: JUNHO | B9: =CONTROLE!I84 -> 3 | D9: =CONTROLE!E84 -> 30 | E9: =CONTROLE!D84 -> 68 | F9: =SUM(B9:E9) -> 101 | G9: =CONTROLE!G84 -> 200 | H9: =SUM(F9:G9) -> 301 | I9: =1781/98 -> 18.173469 | J9: ='REFERENCIA PML'!C8 -> 25.71 | K9: =557/1781 -> 0.31274565 | L9: ='REFERENCIA PML'!E8 -> 33.57 | M9: =10825.84/452 -> 23.950973 | O9: ='REFERENCIA PML'!C15 -> 24.18 | P9: =3938/10825.84 -> 0.3637593 | Q9: ='REFERENCIA PML'!E15 -> 42.48 | R9: =1087/44 -> 24.704545 | T9: ='REFERENCIA PML'!C22 -> 26.36 | U9: =669.5/1087 -> 0.61591536 | V9: ='REFERENCIA PML'!E22 -> 47.24
A10: JULHO | B10: =CONTROLE!I100 -> 5 | D10: =CONTROLE!E100 -> 50 | E10: =CONTROLE!D100 -> 129 | F10: =D10+E10 -> 179 | G10: =CONTROLE!G100 -> 300 | H10: =SUM(F10:G10) -> 479 | I10: =12773.9498/630 -> 20.276111 | J10: ='REFERENCIA PML'!C9 -> 23.15 | K10: =2273.5/12773.9498 -> 0.17797941 | L10: ='REFERENCIA PML'!E9 -> 28.53 | M10: =11025.5209/520 -> 21.202925 | N10: =M10/O10 -> 0.86826064 | O10: ='REFERENCIA PML'!C16 -> 24.42 | P10: =3500.0003/11025.5209 -> 0.31744535 | Q10: ='REFERENCIA PML'!E16 -> 39.99 | R10: — | S10: — | T10: — | U10: — | V10: —
A11: AGOSTO
A12: SETEMBRO
A13: OUTUBRO
A14: NOVEMBRO
A15: DEZEMBRO

Sheet AMANDA
B2: Amanda | H2: MATRIZ | M2: FILIAL 1 | P2: FILIAL 2
A3: MÊS | B3: Total Pacotes Vendidos | C3: Premiação | Pacotes | | D3: Premiação | Meta | loja | E3: Total | F3: Assiduidade R$ | G3: Total Recebido R$ | H3: PMO R$ | I3: PMO/PML | J3: PML | K3: Pg Antecipado Operador % | L3: Pg Antecipado lj % | M3: PMO R$ | N3: PML | O3: % Pg Antecipado | P3: PMO R$ | Q3: PML | R3: % Pg Antecipado
A4: JANEIRO | B4: - | D4: - | E4: 0 | G4: =SUM(E4:F4) -> 0 | H4: - | I4: - | K4: - | L4: ='REFERENCIA PML'!E3 -> 23.87 | M4: - | N4: - | O4: - | P4: - | Q4: - | R4: -
A5: FEVEREIRO | B5: - | C5: - | D5: - | E5: - | G5: =SUM(E5:F5) -> 0 | H5: - | I5: - | K5: - | L5: ='REFERENCIA PML'!E4 -> 33.93 | M5: - | N5: - | O5: - | P5: - | Q5: - | R5: -
A6: MARÇO | B6: - | C6: - | D6: - | E6: - | F6: 0 | G6: =SUM(E6:F6) -> 0 | H6: R$ 14,53 | I6: 0.614 | K6: 0.0151 | L6: ='REFERENCIA PML'!E5 -> 30.84 | M6: — | N6: — | O6: — | P6: — | Q6: — | R6: —
A7: ABRIL | B7: =CONTROLE!I55 -> 2 | C7: =CONTROLE!E55 -> 20 | D7: =CONTROLE!D55 -> 338 | E7: =C7+D7 -> 358 | F7: 300 | G7: =SUM(E7:F7) -> 658 | H7: 18.58 | J7: ='REFERENCIA PML'!C6 -> 23.91 | K7: 0.232 | L7: ='REFERENCIA PML'!E6 -> 30.52
A8: MAIO | B8: =CONTROLE!I66 -> 4 | C8: =CONTROLE!E66 -> 40 | D8: =CONTROLE!D66 -> 421 | E8: =C8+D8 -> 461 | F8: =CONTROLE!G66 -> 300 | G8: =SUM(E8:F8) -> 761 | H8: 26.91 | J8: ='REFERENCIA PML'!C7 -> 26.95 | K8: 0.3446 | L8: ='REFERENCIA PML'!E7 -> 33.85
A9: JUNHO | B9: =CONTROLE!I82 -> 7 | C9: =CONTROLE!E82 -> 70 | D9: =CONTROLE!D82 -> 365 | E9: =C9+D9 -> 435 | F9: =CONTROLE!G82 -> 300 | G9: =SUM(E9:F9) -> 735 | H9: =324/13 -> 24.923077 | J9: ='REFERENCIA PML'!C8 -> 25.71 | K9: =108.5/324 -> 0.33487654 | L9: ='REFERENCIA PML'!E8 -> 33.57
A10: JULHO | B10: =CONTROLE!I98 -> 7 | C10: =CONTROLE!E98 -> 70 | D10: =CONTROLE!D98 -> 379 | E10: =C10+D10 -> 449 | F10: =CONTROLE!G98 -> 300 | G10: =SUM(E10:F10) -> 749 | H10: =17147.3207/641 -> 26.75089 | I10: =H10/J10 -> 1.155546 | J10: ='REFERENCIA PML'!C9 -> 23.15 | K10: =7302.0998/17147.3207 -> 0.42584494 | L10: ='REFERENCIA PML'!E9 -> 28.53 | M10: — | N10: — | O10: — | P10: — | Q10: — | R10: —
A11: AGOSTO

Sheet PRISCILA
B2: Priscila | H2: MATRIZ | M2: FILIAL 1 | Q2: FILIAL 2 | U2: Alvejamento | V2: Hidratação | W2: Kits | X2: Demais Serviços
A3: MÊS | B3: Total Pacotes Vendidos | C3: Premiação | Pacotes | | D3: Premiação | Meta | loja | E3: Total | F3: Assiduidade R$ | G3: Total Recebido R$ | H3: PMO R$ | I3: PMO/PML | J3: PML R$ | K3: Pg Antecipado Operador % | L3: Pg Antecipado lj % | M3: PMO R$ | N3: PML R$ | O3: Pg Antecipado Operador % | P3: Pg Antecipado lj % | Q3: PMO R$ | R3: PML R$ | S3: Pg Antecipado Operador % | T3: Pg Antecipado lj %
A4: JANEIRO | B4: - | C4: - | D4: - | E4: - | G4: =SUM(E4:F4) -> 0 | H4: - | I4: - | K4: - | M4: - | O4: - | Q4: - | S4: - | T4: -
A5: FEVEREIRO | B5: - | C5: - | D5: - | E5: - | G5: =SUM(E5:F5) -> 0 | H5: - | I5: - | K5: - | M5: - | O5: - | Q5: - | S5: - | T5: -
A6: MARÇO | B6: - | C6: - | D6: - | E6: - | F6: - | G6: =SUM(E6:F6) -> 0 | H6: R$ 13,95 | I6: 0.589 | K6: 0.0242 | L6: ='REFERENCIA PML'!E5 -> 30.84 | M6: R$ 37,38 | O6: 0.0661 | Q6: — | S6: — | T6: —
A7: ABRIL | B7: =CONTROLE!I54 -> 1 | C7: =CONTROLE!E54 -> 10 | D7: =CONTROLE!D54 -> 56 | E7: =C7+D7 -> 66 | F7: =CONTROLE!G54 -> 200 | G7: =SUM(E7:F7) -> 266 | H7: 12.94 | J7: ='REFERENCIA PML'!C6 -> 23.91 | K7: 0.072 | L7: ='REFERENCIA PML'!E6 -> 30.52 | M7: 12.9 | N7: ='REFERENCIA PML'!C14 -> 25.84 | O7: 0.651 | Q7: 19.51 | R7: ='REFERENCIA PML'!C20 -> 22.47 | S7: 0.314 | T7: 0.314
A8: MAIO | B8: =CONTROLE!I71 -> 2 | C8: =CONTROLE!E71 -> 20 | D8: =CONTROLE!D71 -> 73 | E8: =C8+D8 -> 93 | F8: =CONTROLE!G71 -> 300 | G8: =SUM(E8:F8) -> 393 | H8: =2405.9/136 -> 17.690441 | J8: ='REFERENCIA PML'!C7 -> 26.95 | K8: =1210.9/2405.9 -> 0.50330438 | L8: ='REFERENCIA PML'!E7 -> 33.85 | Q8: =3121.5/90 -> 34.683333 | R8: ='REFERENCIA PML'!C21 -> 25.34 | S8: =1380.5/3121.5 -> 0.44225533 | T8: ='REFERENCIA PML'!E21 -> 45.49 | U8: 1 | V8: 1
A9: JUNHO | B9: =CONTROLE!I86 -> 0 | C9: =CONTROLE!E86 -> 0 | D9: =CONTROLE!D86 -> 68 | E9: =SUM(C9:D9) -> 68 | F9: =CONTROLE!G86 -> 100 | G9: =SUM(E9:F9) -> 168 | H9: =1023.86/33 -> 31.026061 | J9: ='REFERENCIA PML'!C8 -> 25.71 | K9: =93.5/1023.86 -> 0.091321079 | L9: ='REFERENCIA PML'!E8 -> 33.57 | M9: =5746/296 -> 19.412162 | N9: ='REFERENCIA PML'!C15 -> 24.18 | O9: =1593.5/5746 -> 0.27732336 | P9: ='REFERENCIA PML'!E15 -> 42.48 | Q9: =2676.5/117 -> 22.876068 | R9: ='REFERENCIA PML'!C22 -> 26.36 | S9: =1125.5/2676.5 -> 0.42051186 | T9: ='REFERENCIA PML'!E22 -> 47.24
A10: JULHO | B10: =CONTROLE!I103 -> 0 | C10: =CONTROLE!E103 -> 0 | D10: =CONTROLE!D103 -> 0 | E10: =C10+D10 -> 0 | F10: =CONTROLE!G103 -> 0 | G10: =SUM(E10:F10) -> 0 | H10: =3880.0003/270 -> 14.370371 | I10: =H10/J10 -> 0.62075039 | J10: ='REFERENCIA PML'!C9 -> 23.15 | K10: =795/3880.0003 -> 0.20489689 | L10: ='REFERENCIA PML'!E9 -> 28.53 | M10: — | N10: — | O10: — | P10: — | Q10: =4220.9801/222 -> 19.013424 | R10: ='REFERENCIA PML'!C23 -> 21.59 | S10: =1271.9999/4220.9801 -> 0.30135179 | T10: ='REFERENCIA PML'!E23 -> 28.28
A11: AGOSTO

Sheet SIMONE
A2: Simone
A3: MÊS | B3: Premiação | Meta | loja | C3: Assiduidade R$ | D3: Total Recebido R$
A4: JANEIRO | B4: =CONTROLE!D8 -> 394 | D4: =SUM(B4:C4) -> 394
A5: FEVEREIRO | B5: - | C5: - | D5: =SUM(C5) -> 0
A6: MARÇO | B6: =CONTROLE!D34 -> 449 | C6: =CONTROLE!G34 -> 300 | D6: =CONTROLE!H34 -> 749
A7: ABRIL | B7: =CONTROLE!D45 -> 338 | C7: 300 | D7: =SUM(B7+C7) -> 638
A8: MAIO | B8: =CONTROLE!D65 -> 421 | C8: =CONTROLE!G65 -> 300 | D8: =SUM(B8+C8) -> 721
A9: JUNHO | B9: =CONTROLE!D81 -> 365 | C9: =CONTROLE!G81 -> 300 | D9: =SUM(B9:C9) -> 665
A10: JULHO | B10: =CONTROLE!D97 -> 0 | C10: =CONTROLE!G97 -> 0 | D10: =SUM(B10:C10) -> 0
A11: AGOSTO

Sheet LARISSA
A1: LARISSA
A2: Mês | B2: Peças Passadas | C2: Extras | D2: Premiação | E2: | Meta | loja | F2: Total | G2: Assiduidade | H2: Total Recebido R$
A3: JANEIRO | B3: =CONTROLE!L6 -> 129 | C3: =CONTROLE!M6 -> 24 | D3: =C3*CONTROLE!K6 -> 12 | E3: =CONTROLE!D6 -> 394 | F3: =SUM(D3:E3) -> 406 | G3: - | H3: =SUM(F3:G3) -> 406
A4: FEVEREIRO | B4: =CONTROLE!L19 -> 1245 | C4: =CONTROLE!M19 -> 191 | D4: =CONTROLE!F19 -> 95.5 | E4: =CONTROLE!D19 -> 302 | F4: =SUM(D4:E4) -> 397.5 | G4: 300 | H4: =SUM(F4:G4) -> 697.5
A5: MARÇO | B5: =CONTROLE!L32 -> 1834 | C5: =CONTROLE!M32 -> 295 | D5: =CONTROLE!F32 -> 147.5 | E5: =CONTROLE!D32 -> 449 | F5: =SUM(D5:E5) -> 596.5 | G5: R$ 300,00 | H5: =SUM(F5:G5) -> 596.5
A6: ABRIL | B6: 2063 | C6: 621 | D6: =310.5 -> 310.5 | E6: =CONTROLE!D47 -> 338 | F6: =SUM(D6:E6) -> 648.5 | G6: =CONTROLE!G47 -> 300 | H6: =SUM(F6:G6) -> 948.5
A7: MAIO | B7: 1447 | C7: 137 | D7: 68.5 | E7: =CONTROLE!D63 -> 421 | F7: =SUM(D7:E7) -> 489.5 | G7: =CONTROLE!G63 -> 300 | H7: =SUM(F7:G7) -> 789.5
A8: JUNHO | B8: =CONTROLE!L79 -> 2218 | C8: =CONTROLE!M79 -> 726 | D8: =CONTROLE!F79 -> 363 | E8: =CONTROLE!D79 -> 365 | F8: =SUM(D8:E8) -> 728 | G8: =CONTROLE!G79 -> 300 | H8: =SUM(F8:G8) -> 1028
A9: JULHO | B9: =CONTROLE!L95 -> 2367 | C9: =CONTROLE!M95 -> 738 | D9: =C9*CONTROLE!K95 -> 369 | E9: =CONTROLE!D95 -> 379 | F9: =SUM(D9:E9) -> 748 | G9: =CONTROLE!G95 -> 300 | H9: =SUM(F9:G9) -> 1048
A10: AGOSTO | F10: =SUM(D10:E10) -> 0 | H10: =SUM(E10:G10) -> 0
A11: SETEMBRO | F11: =SUM(D11:E11) -> 0 | H11: =SUM(E11:G11) -> 0
A12: OUTUBRO | F12: =SUM(D12:E12) -> 0 | H12: =SUM(E12:G12) -> 0
A13: NOVEMBRO | F13: =SUM(D13:E13) -> 0 | H13: =SUM(E13:G13) -> 0
A14: DEZEMBRO | F14: =SUM(D14:E14) -> 0 | H14: =SUM(E14:G14) -> 0

Sheet VERA
A1: VERA
A2: Mês | B2: Peças Passadas | C2: Extras | D2: Premiação | E2: | Meta | loja | F2: Total | G2: Assiduidade | H2: Total Recebido R$
A3: JANEIRO | G3: -
A4: FEVEREIRO | G4: -
A5: MARÇO | G5: -
A6: ABRIL | G6: -
A7: MAIO | G7: -
A8: JUNHO | G8: -
A9: JULHO | B9: =CONTROLE!L96 -> 510 | C9: =CONTROLE!M96 -> 6 | D9: =C9*CONTROLE!K96 -> 1.8 | E9: =CONTROLE!D96 -> 0 | F9: =SUM(D9:E9) -> 1.8 | G9: =CONTROLE!G96 -> 154 | H9: =SUM(F9:G9) -> 155.8
A10: AGOSTO | F10: =SUM(D10:E10) -> 0 | H10: =SUM(E10:G10) -> 0
A11: SETEMBRO | F11: =SUM(D11:E11) -> 0 | H11: =SUM(E11:G11) -> 0
A12: OUTUBRO | F12: =SUM(D12:E12) -> 0 | H12: =SUM(E12:G12) -> 0
A13: NOVEMBRO | F13: =SUM(D13:E13) -> 0 | H13: =SUM(E13:G13) -> 0
A14: DEZEMBRO | F14: =SUM(D14:E14) -> 0 | H14: =SUM(E14:G14) -> 0

Sheet CONSOLIDADO OPERADOR — MEDIA 
A1: CONSOLIDADO POR OPERADOR — MÉDIA JAN/FEV/MAR 2026
B3: JANEIRO | E3: FEVEREIRO | H3: MARCO
A4: Operador | B4: PMO | C4: % PML | D4: % Antecipado Lj | E4: PMO | F4: % PML | G4: % Antecipado Lj | H4: PMO | I4: % PML | J4: % Antecipado Lj
A5: Rafael | B5: R$ 22,61 | C5: 1.029 | D5: 0.0246 | E5: R$ 26,03 | F5: 1.225 | G5: 0.0042 | H5: R$ 20,98 | I5: 0.91 | J5: 0.0117
A6: Renata | B6: R$ 17,37 | C6: 0.749 | D6: 0.0335 | E6: R$ 17,00 | F6: 0.816 | G6: 0.0016 | H6: — | I6: — | J6: —
A7: Isabela | B7: R$ 18,83 | C7: 0.881 | D7: 0.5169 | E7: R$ 19,79 | F7: 0.906 | G7: 0.4054 | H7: R$ 19,45 | I7: 0.879 | J7: 0.2188
A8: Camila | B8: R$ 22,75 | C8: 0.98 | D8: 0.3656 | E8: R$ 20,82 | F8: 0.999 | G8: 0.315 | H8: R$ 24,45 | I8: 1.032 | J8: 0.5761
A9: Cristina | B9: R$ 22,16 | C9: 0.955 | D9: 0.3441 | E9: — | F9: — | G9: — | H9: — | I9: — | J9: —
A10: Beatriz | B10: R$ 23,71 | C10: 0.927 | D10: 0.3271 | E10: R$ 18,55 | F10: 0.824 | G10: 0.4012 | H10: R$ 24,18 | I10: 0.984 | J10: 0.6529
A11: Fernanda | B11: R$ 20,11 | C11: 0.94 | D11: 0.4751 | E11: R$ 18,29 | F11: 0.84 | G11: 0.1982 | H11: R$ 19,52 | I11: 0.883 | J11: 0.5168
A12: Sabrina | B12: — | C12: — | D12: — | E12: R$ 17,00 | F12: 0.743 | G12: 0 | H12: R$ 26,48 | I12: 1.13 | J12: 0.107
A13: Carolina | B13: R$ 19,23 | C13: 0.775 | D13: 0.1778 | E13: R$ 19,92 | F13: 0.916 | G13: 0.1215 | H13: R$ 18,44 | I13: 0.784 | J13: 0.1611
A14: Gabriela | B14: R$ 21,03 | C14: 0.861 | D14: 0.2523 | E14: R$ 17,50 | F14: 0.84 | G14: 0.4703 | H14: — | I14: — | J14: —
A15: Amanda | B15: — | C15: — | D15: — | E15: — | F15: — | G15: — | H15: R$ 14,53 | I15: 0.614 | J15: 0.0151
A16: Priscila | B16: — | C16: — | D16: — | E16: — | F16: — | G16: — | H16: R$ 25,67 | I16: 1.139 | J16: 0.0451

Sheet ISABELA
B2: Isabela | I2: MATRIZ | L2: FILIAL 1 | P2: FILIAL 2
A3: MÊS | B3: Total Pacotes Vendidos | C3: COMISSÃO | D3: Premiação | Pacotes | | E3: Premiação | Meta | loja | F3: Total | G3: Assiduidade R$ | H3: Total Recebido R$ | I3: PMO R$ | J3: PMO/PML | K3: % Pg Antecipado | L3: PMO R$ | M3: PMO/PML | N3: PML | O3: % Pg Antecipado | P3: PMO R$ | Q3: PMO/PML | R3: % Pg Antecipado
A4: JANEIRO | B4: =CONTROLE!I9 -> 1 | C4: 0 | D4: =CONTROLE!E9 -> 10 | E4: =CONTROLE!D9 -> 117 | F4: =D4+E4 -> 127 | H4: =SUM(F4:G4) -> 127 | I4: — | J4: — | K4: — | L4: R$ 18,83 | M4: 0.881 | N4: ='REFERENCIA PML'!C10 -> R$ 21,38 | O4: 0.5169 | P4: — | Q4: — | R4: —
A5: FEVEREIRO | B5: =CONTROLE!I22 -> 3 | D5: =CONTROLE!E22 -> 30 | E5: =META!F17 -> 96 | F5: =D5+E5 -> 126 | G5: 300 | H5: =SUM(F5:G5) -> 426 | I5: — | J5: — | K5: — | L5: R$ 19,79 | M5: 0.906 | N5: ='REFERENCIA PML'!C11 -> 22.14 | O5: 0.4054 | P5: — | Q5: — | R5: —
A6: MARÇO | B6: =CONTROLE!I35 -> 1 | D6: =CONTROLE!E35 -> 10 | E6: =CONTROLE!D35 -> 124 | F6: =D6+E6 -> 134 | G6: 0 | H6: =SUM(F6:G6) -> 134 | I6: — | J6: — | K6: — | L6: R$ 19,45 | M6: 0.879 | N6: ='REFERENCIA PML'!C12 -> 22.52 | O6: 0.2188 | P6: — | Q6: — | R6: —
A7: ABRIL | B7: =CONTROLE!I50 -> 1 | D7: =CONTROLE!E50 -> 10 | E7: 0 | F7: =D7+E7 -> 10 | G7: 0 | H7: =SUM(F7:G7) -> 10 | I7: — | J7: — | K7: — | L7: 18.8 | N7: ='REFERENCIA PML'!C14 -> 25.84 | O7: 0.418 | P7: — | Q7: — | R7: —
A8: MAIO
A9: JUNHO
A10: JULHO
A11: AGOSTO
A12: SETEMBRO
A13: OUTUBRO
A14: NOVEMBRO
A15: DEZEMBRO

Sheet MARINA
A1: MARINA
A2: Mês | B2: Peças Passadas | C2: Extra | D2: Premiação | E2: | Meta | loja | F2: Total | G2: Assiduidade | H2: Total Reecebido R$
A3: JANEIRO | B3: =CONTROLE!L7 -> 2824 | C3: =CONTROLE!M7 -> 1278 | D3: =CONTROLE!F7 -> 383.4 | E3: =CONTROLE!D7 -> 394 | F3: =SUM(D3:E3) -> 777.4 | H3: =SUM(F3:G3) -> 777.4
A4: FEVEREIRO | B4: =CONTROLE!L20 -> 1590 | C4: =CONTROLE!M20 -> 345 | D4: =CONTROLE!F20 -> 103.5 | E4: =CONTROLE!D20 -> 302 | F4: =SUM(D4:E4) -> 405.5 | G4: 300 | H4: =SUM(F4:G4) -> 705.5
A5: MARÇO | B5: =CONTROLE!L33 -> 1859 | C5: =CONTROLE!M33 -> 536 | D5: =CONTROLE!F33 -> 160.8 | E5: =CONTROLE!D33 -> 449 | F5: =SUM(D5:E5) -> 609.8 | G5: 300 | H5: =SUM(F5:G5) -> 909.8
A6: ABRIL | B6: 1404 | C6: 345 | D6: =C6*0.3 -> 103.5 | E6: 0 | F6: =SUM(D6:E6) -> 103.5 | G6: - | H6: =SUM(F6:G6) -> 103.5
A7: MAIO | B7: 1870 | C7: 394 | D7: =C7*0.3 -> 118.2 | E7: =CONTROLE!D64 -> 421 | F7: =SUM(D7:E7) -> 539.2 | G7: =CONTROLE!G64 -> 300 | H7: =SUM(F7:G7) -> 839.2
A8: JUNHO | B8: =CONTROLE!L80 -> 1170 | C8: =CONTROLE!M80 -> 390 | D8: =C8*0.3 -> 117 | F8: =SUM(D8:E8) -> 117 | H8: =SUM(F8:G8) -> 117
A9: JULHO | D9: =C9*0.3 -> 0 | F9: =SUM(D9:E9) -> 0 | H9: =SUM(F9:G9) -> 0
A10: AGOSTO | F10: =SUM(D10:E10) -> 0 | H10: =SUM(F10:G10) -> 0
A11: SETEMBRO | F11: =SUM(D11:E11) -> 0 | H11: =SUM(F11:G11) -> 0
A12: OUTUBRO | F12: =SUM(D12:E12) -> 0 | H12: =SUM(F12:G12) -> 0
A13: NOVEMBRO | F13: =SUM(D13:E13) -> 0 | H13: =SUM(F13:G13) -> 0
A14: DEZEMBRO | F14: =SUM(D14:E14) -> 0 | H14: =SUM(F14:G14) -> 0
